Workbook
Name Couples_std: [1]Indicateurs!#REF!
Name Etat_fiches: [1]Indicateurs!$B$4:$B$8
Name Liste_avancement: #REF!
Name Liste_avancement: #REF!
Name Livraison: '[1]Liste '!$B$28:$B$32
Name Parametres_CodeDocument: '[2]6)Entête'!$C$11
Name Parametres_DateMiseaJour: '[2]6)Entête'!$C$8
Name TYPE: '[1]Liste '!$B$14:$B$25
Name Zone_véhicule: '[1]Liste '!$B$36:$B$47

Sheet Table APOQUA files
A1: For Nouhayla | B1: For Layla | C1: for Zaineb | E1: APOQUA FILE INDICATION | J1: Status APOQUA file
D2: Reference | E2: APOQUA designation (Français) | F2: APOQUA designation (English) | G2: PSA DEC | H2: Lot | I2: Vehicle area | J2: Creation date | K2: Last modification | L2: Status | M2: in file poro | N2: in pfr for Lionel | O2: 400list ? YES/NO/TBC CANCELED | P2: B13 3116 ? YES/NO/NA TBC/CANCELED | Q2: Check Responsible | R2: Comment
A3: X | D3: 01266_09_00147 | E3: PARE CHOC AV - ARMATURE | F3: FRT BUMPER - LOWER FRAME | G3: R1A | H3: EXT | I3: Front Face and Hood | J3: 39987 | K3: 45173 | L3: Applicable | M3: =IF(ISNA(VLOOKUP(D3,'[3]Table APOQUA files'!$B:$B,1,FALSE)),"NO","YES") -> YES | N3: =IF(ISNA(VLOOKUP(D3,'Base PFR table'!K:K,1,FALSE)),"NO","YES") -> NO | O3: TBC | P3: TBC
A4: X | D4: 01266_09_00155 | E4: DECORS ENJOLIVEURS PDB | F4: DASHBOARD TRIM EMBELLISHMENTS | G4: S1A | H4: PDC | I4: Dashboard and console | J4: 39989 | K4: 43011 | L4: To be updated | M4: =IF(ISNA(VLOOKUP(D4,'[3]Table APOQUA files'!$B:$B,1,FALSE)),"NO","YES") -> YES | N4: =IF(ISNA(VLOOKUP(D4,'Base PFR table'!K:K,1,FALSE)),"NO","YES") -> NO | O4: TBC | P4: TBC
A5: X | D5: 01266_09_00156 | E5: ENJOLIVEUR DE PLAQUE IMMATRICULATION | F5: REGISTRATION PLATE FINISHER | G5: R3F | H5: EXT | I5: Rear Face and Tailgate | J5: 39989 | K5: 45209 | L5: Approved | M5: =IF(ISNA(VLOOKUP(D5,'[3]Table APOQUA files'!$B:$B,1,FALSE)),"NO","YES") -> YES | N5: =IF(ISNA(VLOOKUP(D5,'Base PFR table'!K:K,1,FALSE)),"NO","YES") -> YES | O5: TBC | P5: TBC
A6: X | D6: 01266_09_00299 | E6: TRAVERSE SUP FAÇADE BLOC AVANT | F6: FRT BUMPER - LOWER FRAME (RADIATOR SCREEN SUPPORT) | G6: R1A | H6: EXT | I6: Front Face and Hood | J6: 40051 | K6: 45222 | L6: To be updated | M6: =IF(ISNA(VLOOKUP(D6,'[3]Table APOQUA files'!$B:$B,1,FALSE)),"NO","YES") -> YES | N6: =IF(ISNA(VLOOKUP(D6,'Base PFR table'!K:K,1,FALSE)),"NO","YES") -> NO | O6: TBC | P6: TBC
A7: X | D7: 01266_10_00199 | E7: BOITIER-SECU-DML | G7: 0 | H7: - | I7: Harness and ECUs | J7: 40212 | K7: 42893 | L7: To be updated | M7: =IF(ISNA(VLOOKUP(D7,'[3]Table APOQUA files'!$B:$B,1,FALSE)),"NO","YES") -> YES | N7: =IF(ISNA(VLOOKUP(D7,'Base PFR table'!K:K,1,FALSE)),"NO","YES") -> NO | O7: TBC | P7: TBC
A8: X | D8: 01266_10_00632 | E8: PLANCHE DE BORD SUR CAISSE | F8: DASHBOARD ON BODY | G8: S1A | H8: PDC | I8: Dashboard and console | J8: 40294 | K8: 45218 | L8: Approved | M8: =IF(ISNA(VLOOKUP(D8,'[3]Table APOQUA files'!$B:$B,1,FALSE)),"NO","YES") -> YES | N8: =IF(ISNA(VLOOKUP(D8,'Base PFR table'!K:K,1,FALSE)),"NO","YES") -> YES | O8: TBC | P8: TBC
A9: X | D9: 01266_10_00634 | E9: PARE CHOC AR - PEAU | F9: RR BUMPER - SKIN | G9: R1A | H9: EXT | I9: Rear Face and Tailgate | J9: 40294 | K9: 45600 | L9: Applicable | M9: =IF(ISNA(VLOOKUP(D9,'[3]Table APOQUA files'!$B:$B,1,FALSE)),"NO","YES") -> YES | N9: =IF(ISNA(VLOOKUP(D9,'Base PFR table'!K:K,1,FALSE)),"NO","YES") -> NO | O9: TBC | P9: TBC
D10: 01266_10_00635 | E10: PARE CHOC AV - SUPPORT SUPERIEUR | F10: FRONT BUMPER UPP SUPPORT | G10: R1A | H10: EXT | I10: Front Face and Hood | J10: 40295 | K10: 40913 | L10: Cancelled | M10: =IF(ISNA(VLOOKUP(D10,'[3]Table APOQUA files'!$B:$B,1,FALSE)),"NO","YES") -> YES | N10: =IF(ISNA(VLOOKUP(D10,'Base PFR table'!K:K,1,FALSE)),"NO","YES") -> NO | O10: CANCELED | P10: CANCELED
A11: X | D11: 01266_10_00636 | E11: MFRH - MATRICE FUSIBLE RELAIS HABITACLE | F11: MFRH - CABIN RELAY FUSIBLE UNIT | G11: Z5U | H11: AEE | I11: Harness and ECUs | J11: 40295 | K11: 42779 | L11: To be updated | M11: =IF(ISNA(VLOOKUP(D11,'[3]Table APOQUA files'!$B:$B,1,FALSE)),"NO","YES") -> YES | N11: =IF(ISNA(VLOOKUP(D11,'Base PFR table'!K:K,1,FALSE)),"NO","YES") -> NO | O11: TBC | P11: TBC
D12: 01266_10_00637 | E12: BOITIER SECURISATION ANTIVOL ELECTRIQUE SECU-AVE | F12: ELECTRIC ANTI-THEFT SAFETY-AVE SECU-AVE | G12: Z8G | H12: EEH | I12: Harness and ECUs | J12: 40295 | K12: 42940 | L12: Cancelled | M12: =IF(ISNA(VLOOKUP(D12,'[3]Table APOQUA files'!$B:$B,1,FALSE)),"NO","YES") -> YES | N12: =IF(ISNA(VLOOKUP(D12,'Base PFR table'!K:K,1,FALSE)),"NO","YES") -> NO | O12: CANCELED | P12: CANCELED
A13: X | D13: 01266_10_00642 | E13: GARNITURE DE SUPPORT TABLETTE AR | F13: RR PARCEL SHELF SUPPORT TRIM | G13: X3D | H13: INT | I13: Interior Trims | J13: 40295 | K13: 45686 | L13: Approved | M13: =IF(ISNA(VLOOKUP(D13,'[3]Table APOQUA files'!$B:$B,1,FALSE)),"NO","YES") -> YES | N13: =IF(ISNA(VLOOKUP(D13,'Base PFR table'!K:K,1,FALSE)),"NO","YES") -> NO | O13: TBC | P13: TBC
A14: X | D14: 01266_10_00643 | E14: SIEGES RANG1 | F14: SEATS RANK 1 | G14: Y1A | H14: ASS | I14: Seats and safety belts | J14: 40295 | K14: 45643 | L14: Approved | M14: =IF(ISNA(VLOOKUP(D14,'[3]Table APOQUA files'!$B:$B,1,FALSE)),"NO","YES") -> YES | N14: =IF(ISNA(VLOOKUP(D14,'Base PFR table'!K:K,1,FALSE)),"NO","YES") -> YES | O14: TBC | P14: TBC
A15: X | D15: 01266_10_00644 | E15: SIEGE INDIVIDUEL RANG 2 | F15: INDIVIDUAL_SEAT_RANK_2 | G15: Y2A | H15: ASS | I15: Seats and safety belts | J15: 40295 | K15: 45379 | L15: Approved | M15: =IF(ISNA(VLOOKUP(D15,'[3]Table APOQUA files'!$B:$B,1,FALSE)),"NO","YES") -> YES | N15: =IF(ISNA(VLOOKUP(D15,'Base PFR table'!K:K,1,FALSE)),"NO","YES") -> NO | O15: TBC | P15: TBC
A16: X | D16: 01266_10_00645 | E16: RAIL SUPPORT SIEGE CENTRALE (SIEGES RANG 3) | F16: SEAT SUPPORT RAIL CENTAL (SEATS ROW 3) | G16: Y3A | H16: ASS | I16: Seats and safety belts | J16: 40295 | K16: 44335 | L16: To be updated | M16: =IF(ISNA(VLOOKUP(D16,'[3]Table APOQUA files'!$B:$B,1,FALSE)),"NO","YES") -> YES | N16: =IF(ISNA(VLOOKUP(D16,'Base PFR table'!K:K,1,FALSE)),"NO","YES") -> NO | O16: TBC | P16: TBC
A17: X | D17: 01266_10_00732 | E17: BPGA - BOITIER DE LA PROTECTION DE LA GESTION DES ALIMENTATION | F17: BPGA - SUPPLY MANAGEMENT PROTECTION UNIT | G17: Z5U | H17: AEE | I17: Harness and ECUs | J17: 40304 | K17: 40561 | L17: To be updated | M17: =IF(ISNA(VLOOKUP(D17,'[3]Table APOQUA files'!$B:$B,1,FALSE)),"NO","YES") -> YES | N17: =IF(ISNA(VLOOKUP(D17,'Base PFR table'!K:K,1,FALSE)),"NO","YES") -> NO | O17: TBC | P17: TBC
D18: 01266_10_00733 | E18: BOÎTIER ECLAIRAGE MEMORISATION (PORTE PASSAGER) (BEM) | H18: - | I18: Harness and ECUs | J18: 40304 | K18: 40304 | L18: Cancelled | M18: =IF(ISNA(VLOOKUP(D18,'[3]Table APOQUA files'!$B:$B,1,FALSE)),"NO","YES") -> YES | N18: =IF(ISNA(VLOOKUP(D18,'Base PFR table'!K:K,1,FALSE)),"NO","YES") -> NO | O18: CANCELED | P18: CANCELED
A19: X | D19: 01266_10_00734 | E19: EQUILIBREUR DE CAPOT | F19: HOOD STABILIZER | G19: N2A | H19: EXT | I19: Front Face and Hood | J19: 40304 | K19: 45432 | L19: Approved | M19: =IF(ISNA(VLOOKUP(D19,'[3]Table APOQUA files'!$B:$B,1,FALSE)),"NO","YES") -> YES | N19: =IF(ISNA(VLOOKUP(D19,'Base PFR table'!K:K,1,FALSE)),"NO","YES") -> NO | O19: TBC | P19: TBC
D20: 01266_10_00735 | E20: VOLET MOTORISE - MAF/MVM | F20: MULTIFONCTION ASSISTANCE CLOSING MODULE | G20: N2E | H20: OUV | I20: Rear Face and Tailgate | J20: 40304 | K20: 08/03/2023 | L20: Cancelled | M20: =IF(ISNA(VLOOKUP(D20,'[3]Table APOQUA files'!$B:$B,1,FALSE)),"NO","YES") -> YES | N20: =IF(ISNA(VLOOKUP(D20,'Base PFR table'!K:K,1,FALSE)),"NO","YES") -> NO | O20: CANCELED | P20: CANCELED
A21: X | D21: 01266_10_00736 | E21: SUPPORT MOTEUR INTERMEDIAIRE DROIT (SMID) | F21: RIGHT INTERMEDIATE ENGINE SUPPORT (SMID) | G21: D11 | H21: ATR | I21: Engine and Gearbox Adaptation | J21: 40304 | K21: 42667 | L21: To be updated | M21: =IF(ISNA(VLOOKUP(D21,'[3]Table APOQUA files'!$B:$B,1,FALSE)),"NO","YES") -> YES | N21: =IF(ISNA(VLOOKUP(D21,'Base PFR table'!K:K,1,FALSE)),"NO","YES") -> NO | O21: TBC | P21: TBC
D22: 01266_10_00737 | E22: BUTEE D'ATTAQUE TRAIN AR DEFORMABLE | F22: DEFORMABLE REAR AXLE ATTACK STOP | G22: E25 | H22: LAS | I22: Liaison au sol | J22: 43636 | K22: 40304 | L22: Cancelled | M22: =IF(ISNA(VLOOKUP(D22,'[3]Table APOQUA files'!$B:$B,1,FALSE)),"NO","YES") -> YES | N22: =IF(ISNA(VLOOKUP(D22,'Base PFR table'!K:K,1,FALSE)),"NO","YES") -> NO | O22: CANCELED | P22: CANCELED
D23: 01266_10_00742 | E23: FIXATION ECRANS AERAULIQUES SOUS-CAISSE (SI AUTOMATIQUE) | F23: UNDER BODY AIR DEFLECTOR MOUNTINGS (IF AUTOMATIC) | H23: - | I23: 0 | J23: 40304 | K23: 41457 | L23: Cancelled | M23: =IF(ISNA(VLOOKUP(D23,'[3]Table APOQUA files'!$B:$B,1,FALSE)),"NO","YES") -> YES | N23: =IF(ISNA(VLOOKUP(D23,'Base PFR table'!K:K,1,FALSE)),"NO","YES") -> NO | O23: CANCELED | P23: CANCELED
D24: 01266_10_00743 | E24: DMT - DISPOSITIF MAINTIEN EN TENTION - CENTRALISE | F24: DMT - VOLTAGE MAINTENANCE DEVICE - CENTRALIZED | G24: Z1D | H24: EEM | I24: Harness and ECUs | J24: 40304 | K24: 43009 | L24: Cancelled | M24: =IF(ISNA(VLOOKUP(D24,'[3]Table APOQUA files'!$B:$B,1,FALSE)),"NO","YES") -> YES | N24: =IF(ISNA(VLOOKUP(D24,'Base PFR table'!K:K,1,FALSE)),"NO","YES") -> NO | O24: CANCELED | P24: CANCELED
A25: X | D25: 01266_10_00744 | E25: CAPTEUR HAUTEUR AV | F25: FRT HEIGHT SENSOR | G25: G76 | H25: HYD | I25: Liaison au sol | J25: 40304 | K25: 45226 | L25: Applicable | M25: =IF(ISNA(VLOOKUP(D25,'[3]Table APOQUA files'!$B:$B,1,FALSE)),"NO","YES") -> YES | N25: =IF(ISNA(VLOOKUP(D25,'Base PFR table'!K:K,1,FALSE)),"NO","YES") -> YES | O25: TBC | P25: TBC
A26: X | D26: 01266_10_00745 | E26: ENJOLIVEUR DE CUSTODE | F26: QUARTER PANEL TRIM* | G26: R3B | H26: OUV | I26: Lateral Face and Doors | J26: 40304 | K26: 45568 | L26: Approved | M26: =IF(ISNA(VLOOKUP(D26,'[3]Table APOQUA files'!$B:$B,1,FALSE)),"NO","YES") -> YES | N26: =IF(ISNA(VLOOKUP(D26,'Base PFR table'!K:K,1,FALSE)),"NO","YES") -> NO | O26: TBC | P26: TBC
A27: X | D27: 01266_10_01125 | E27: GROUPE CLIMATISATION SUR PLANCHE DE BORD | F27: DASHBOARD ON AC UNIT | G27: S1A | H27: PDC | I27: Dashboard and console | J27: 40365 | K27: 43188 | L27: To be updated | M27: =IF(ISNA(VLOOKUP(D27,'[3]Table APOQUA files'!$B:$B,1,FALSE)),"NO","YES") -> YES | N27: =IF(ISNA(VLOOKUP(D27,'Base PFR table'!K:K,1,FALSE)),"NO","YES") -> NO | O27: TBC | P27: TBC
A28: X | D28: 01266_10_01499 | E28: RESERVOIR SCR €6 - REDUCTION CATALYTIQUE SELECTIVE | F28: CATALYTIC NITROGEN OXIDE REDUCTION | G28: B25 | H28: AMO | I28: Engine and Gearbox Adaptation | J28: 40455 | K28: 43026 | L28: Cancelled | M28: =IF(ISNA(VLOOKUP(D28,'[3]Table APOQUA files'!$B:$B,1,FALSE)),"NO","YES") -> YES | N28: =IF(ISNA(VLOOKUP(D28,'Base PFR table'!K:K,1,FALSE)),"NO","YES") -> NO | O28: CANCELED | P28: CANCELED
A29: X | D29: 01266_10_01548 | E29: CROCHET SECURITE CAPOT | F29: HOOK SAFETY HOOD | G29: N2A | H29: EXT | I29: Front Face and Hood | J29: 40464 | K29: 45432 | L29: Approved | M29: =IF(ISNA(VLOOKUP(D29,'[3]Table APOQUA files'!$B:$B,1,FALSE)),"NO","YES") -> YES | N29: =IF(ISNA(VLOOKUP(D29,'Base PFR table'!K:K,1,FALSE)),"NO","YES") -> YES | O29: TBC | P29: TBC
A30: X | D30: 01266_10_01610 | E30: MODULE ENTREE D'AIR PILOTEE | F30: PILOT AIR INPUT MODULE | G30: R1A | H30: EXT | I30: Front Face and Hood | J30: 40476 | K30: 45222 | L30: To be updated | M30: =IF(ISNA(VLOOKUP(D30,'[3]Table APOQUA files'!$B:$B,1,FALSE)),"NO","YES") -> YES | N30: =IF(ISNA(VLOOKUP(D30,'Base PFR table'!K:K,1,FALSE)),"NO","YES") -> NO | O30: TBC | P30: TBC
A31: X | D31: 01266_10_01772 | E31: CLOISONS ANTI RECYCLAGE | F31: PANEL RADIATOR SHROUD | G31: K3H | H31: STR | I31: Front Face and Hood | J31: 40499 | K31: 45390 | L31: Cancelled | M31: =IF(ISNA(VLOOKUP(D31,'[3]Table APOQUA files'!$B:$B,1,FALSE)),"NO","YES") -> YES | N31: =IF(ISNA(VLOOKUP(D31,'Base PFR table'!K:K,1,FALSE)),"NO","YES") -> NO | O31: CANCELED | P31: CANCELED
D32: 01266_10_01773 | E32: ECRAN ACOUSTIQUE | F32: SOUND SCREEN | G32: K2E | H32: STR | I32: 0 | J32: 40499 | K32: 40730 | L32: To be updated | M32: =IF(ISNA(VLOOKUP(D32,'[3]Table APOQUA files'!$B:$B,1,FALSE)),"NO","YES") -> YES | N32: =IF(ISNA(VLOOKUP(D32,'Base PFR table'!K:K,1,FALSE)),"NO","YES") -> NO | O32: TBC | P32: TBC
A33: X | D33: 01266_10_01789 | E33: BSG BOITIER SERVITUDE GENERIQUE (BSG-RQ / BSG-TC / BSGS / BSR) | F33: BSG - GENERIC RELAY UNIT | G33: Z5U | H33: AEE | I33: Harness and ECUs | J33: 40501 | K33: 42816 | L33: To be updated | M33: =IF(ISNA(VLOOKUP(D33,'[3]Table APOQUA files'!$B:$B,1,FALSE)),"NO","YES") -> YES | N33: =IF(ISNA(VLOOKUP(D33,'Base PFR table'!K:K,1,FALSE)),"NO","YES") -> NO | O33: TBC | P33: TBC
A34: X | D34: 01266_11_00202 | E34: PARE BOUE AV | F34: FRONT MUDGUARD | G34: K3J | H34: STR | I34: Under Body | J34: 40575 | K34: 45442 | L34: Approved | M34: =IF(ISNA(VLOOKUP(D34,'[3]Table APOQUA files'!$B:$B,1,FALSE)),"NO","YES") -> YES | N34: =IF(ISNA(VLOOKUP(D34,'Base PFR table'!K:K,1,FALSE)),"NO","YES") -> NO | O34: TBC | P34: TBC
A35: X | D35: 01266_11_00203 | E35: PARE BOUE AR | F35: REAR MUDGUARD | G35: K4H | H35: STR | I35: Under Body | J35: 40575 | K35: 12/04/2023 | L35: Applicable | M35: =IF(ISNA(VLOOKUP(D35,'[3]Table APOQUA files'!$B:$B,1,FALSE)),"NO","YES") -> YES | N35: =IF(ISNA(VLOOKUP(D35,'Base PFR table'!K:K,1,FALSE)),"NO","YES") -> NO | O35: TBC | P35: TBC
A36: X | D36: 01266_11_00285 | E36: ELEMENT PORTEUR ASSEMBLAGE | F36: FRONT SHOCK ABSORBER ELEMENTS | G36: E14 | H36: LAS | I36: Liaison au sol | J36: 40584 | K36: 45226 | L36: Approved | M36: =IF(ISNA(VLOOKUP(D36,'[3]Table APOQUA files'!$B:$B,1,FALSE)),"NO","YES") -> YES | N36: =IF(ISNA(VLOOKUP(D36,'Base PFR table'!K:K,1,FALSE)),"NO","YES") -> YES | O36: TBC | P36: TBC
A37: X | D37: 01266_11_00381 | E37: GARNITURE INF DE PIED AV | F37: FRONT PILLAR LOWER TRIM | G37: X3A | H37: INT | I37: Interior Trims | J37: 40598 | K37: 45686 | L37: Current update | M37: =IF(ISNA(VLOOKUP(D37,'[3]Table APOQUA files'!$B:$B,1,FALSE)),"NO","YES") -> YES | N37: =IF(ISNA(VLOOKUP(D37,'Base PFR table'!K:K,1,FALSE)),"NO","YES") -> NO | O37: TBC | P37: TBC
A38: X | D38: 01266_11_00413 | E38: CHARNIERE PORTES AV ET AR - FERRAGE | F38: FRONT AND REAR DOOR HINGES - BIW | G38: K7F/K7G | H38: OUV | I38: Lateral Face and Doors | J38: 40604 | K38: 45348 | L38: Applicable | M38: =IF(ISNA(VLOOKUP(D38,'[3]Table APOQUA files'!$B:$B,1,FALSE)),"NO","YES") -> YES | N38: =IF(ISNA(VLOOKUP(D38,'Base PFR table'!K:K,1,FALSE)),"NO","YES") -> YES | O38: TBC | P38: TBC
A39: X | D39: 01266_11_01492 | E39: GRILLE AUVENT | F39: COWL VENT GRILLE | G39: R3H | H39: STR | I39: Front Face and Hood | J39: 40732 | K39: 45686 | L39: Approved | M39: =IF(ISNA(VLOOKUP(D39,'[3]Table APOQUA files'!$B:$B,1,FALSE)),"NO","YES") -> YES | N39: =IF(ISNA(VLOOKUP(D39,'Base PFR table'!K:K,1,FALSE)),"NO","YES") -> NO | O39: TBC | P39: TBC
A40: X | D40: 01266_11_01943 | E40: AIRBAG PORTE AR | F40: REAR DOOR AIRBAG | G40: U3B | H40: ASS | I40: Lateral Face and Doors | J40: 40809 | K40: 40913 | L40: To be updated | M40: =IF(ISNA(VLOOKUP(D40,'[3]Table APOQUA files'!$B:$B,1,FALSE)),"NO","YES") -> YES | N40: =IF(ISNA(VLOOKUP(D40,'Base PFR table'!K:K,1,FALSE)),"NO","YES") -> NO | O40: TBC | P40: TBC
...

Sheet List fastener in APOQUA files
C4: priority list is on this link (reachable also by FPEE share point*) :
C6: Docinfo
C7: http://docinfogroupe.inetpsa.com/ead/doc/ref.01266_21_00091/v.vc/fiche
C14: *

Sheet PORO table
A1: reference | B1: english designation | C1: psa code | D1: vehicule area | E1: last modification | F1: Status | G1: Ref screw, nut BdL | H1: nb Tightening | I1: Nb Tightening LVE | J1: Ref clip BdL | K1: Nb agrafes BdL | L1: triplet for poro
A2: 01266_22_00523 | B2: FRONT/REAR LASHING EYES | C2: X5E | D2: Interior Trims | E2: 23/02/2023 | F2: Update format to do | G2: - B SOLUTION 9809840080 SCREW H RP18 M6X100 L20 AC8 ZLVFGL FP coef 1 | H2: 0 1 | I2: 0 0 | J2: - - | K2: 0 0 | L2: - HSP10_8_15
A3: 01266_10_00734 | B3: HOOD STABILIZER | C3: N2A | D3: Front Face and Hood | E3: 03/04/2023 | F3: Applicable | G3: - | H3: 0 | I3: 0 | J3: - | K3: 0 | L3: -
A4: 01266_12_00151 | B4: COWL WATER OUTLET | C4: V1C | E4: 24/04/2023 | F4: Applicable | G4: - | H4: 0 | I4: coef | J4: - | K4: 0 | L4: -
A5: 01266_13_00326 | B5: FRONT WHEEL SPEED SENSOR | C5: F68 | D5: Liaison au sol | E5: 31/04/2024 | F5: Approved | G5: - | H5: 0 | I5: coef 1 | J5: - | K5: 0 | L5: TX30_8_15
A6: 01266_17_00696 | B6: DOOR PRESSURE SENSOR | C6: 0 | D6: Lateral Face and Doors | E6: 24/04/2023 | F6: Applicable | G6: - | H6: 0 | I6: coef | J6: - | K6: 0 | L6: -
A7: 01266_19_00600 | B7: REARVIEW MIRROR | C7: T2E | D7: Roof and Roof trim | E7: 18/04/2023 | F7: Applicable | G7: - | H7: 0 | I7: 0 | J7: coef | K7: coef | L7: -
A8: 01266_19_00602 | B8: INTERIOR REARVIEW MIRROR FOOT COVER | C8: T2E | D8: Roof and Roof trim | E8: 18/04/2023 | F8: Applicable | G8: - | H8: 0 | I8: 0 | J8: coef | K8: coef | L8: -
A9: 01266_19_00604 | B9: SENSOR RAIN DETECTION | C9: Z6E | D9: Front Face and Hood | E9: 21/04/2023 | F9: Applicable | G9: - | H9: 0 | I9: coef | J9: - | K9: 0 | L9: -
A10: 01266_19_00606 | B10: AIR EXTRACTOR | C10: V4B | D10: Interior Trims | E10: 18/04/2023 | F10: Applicable | G10: - | H10: 0 | I10: 0 | J10: coef | K10: coef | L10: -
A11: 01266_22_00522 | B11: SUN VISOR HOOK | C11: T2A | D11: Roof and Roof trim | E11: 04/07/2023 | F11: Update format to do | G11: - | H11: 0 | I11: 0 | J11: - | K11: 0 | L11: -
A12: DITV_ATAT07_0009 | B12: TRUNCK CARPET | C12: X5A | D12: Interior Trims | E12: 19/04/2023 | F12: Applicable | G12: - | H12: 0 | I12: 0 | J12: - | K12: 0 | L12: -
A13: DITV_ATAT07_0045 | B13: SHEATH COLUMN (upper and lower) | C13: S1D | D13: Dashboard and console | E13: 05/04/2023 | F13: Update format to do | G13: - | H13: 0 | I13: coef 3 | J13: - | K13: 0 | L13: TX20_2_15
A14: DITV_ATAT07_0051 | B14: TWEETER and GRID TWEETER | C14: Z7D | E14: 03/04/2023 | F14: Applicable | G14: - | H14: 0 | I14: 0 | J14: - | K14: 0 | L14: -
A15: DITV_ATAT07_0285 | B15: BONNET SOUND DEADENING | C15: X1B | D15: Front Face and Hood | E15: 24/04/2023 | F15: Update format to do | G15: - | H15: 0 | I15: 0 | J15: - | K15: 0 | L15: -
A16: DPTA_DMOV05_0956 | B16: INTERIOR FINISHER GUSSET DOOR | C16: X4C | D16: Lateral Face and Doors | E16: 24/04/2023 | F16: Applicable | G16: - | H16: 0 | I16: 0 | J16: - | K16: 0 | L16: -
A17: DPTA_DMOV05_0968 | B17: REGISTRATION PLATE FINISHER | C17: R3F | D17: Rear Face and Tailgate | E17: 29/08/2023 | F17: Applicable | G17: - | H17: 0 | I17: 0 | J17: - | K17: 0 | L17: -
A18: DPTA_DMOV06_0053 | B18: HOOD STOP | C18: N2A | D18: Front Face and Hood | E18: 31/03/2023 | F18: Applicable | G18: - | H18: 0 | I18: 0 | J18: - | K18: 0 | L18: -
A19: DPTA_DMOV06_0110 | B19: SEAL TAILGATE APERTURE | C19: W3A | D19: Rear Face and Tailgate | E19: 19/04/2023 | F19: Applicable | G19: - | H19: 0 | I19: 0 | J19: - | K19: 0 | L19: -
A20: DPTA_DMOV06_0151 | B20: REAR WINDOW WIPER MOTOR | C20: Z6F | D20: Rear Face and Tailgate | E20: 25/04/2023 | F20: Applicable | G20: - | H20: 0 | I20: coef 3 | J20: - | K20: 0 | L20: HSP10_8_15
A21: 01266_22_00761 | B21: FRONT FENDER UPPER FINISHER | C21: R3D | D21: Front Face and Hood | E21: 02/06/2023 | F21: Applicable | G21: - | H21: 0 | I21: 0 | J21: - | K21: 0 | L21: -
A22: 01266_22_00762 | B22: UPPER CAR BODY TRIM | C22: R3C | D22: Lateral Face and Doors | E22: 45229 | F22: Approved | G22: - | H22: 0 | I22: 0 | J22: - | K22: 0 | L22: -
A23: 01266_22_00514 | B23: RR DOOR GUSSET INR FINISHER | C23: X4C | D23: Lateral Face and Doors | E23: 45225 | F23: Applicable | G23: - | H23: 0 | I23: 0 | J23: - | K23: 0 | L23: -
A24: 01266_22_00513 | B24: FINISHER DRIP CHANNEL | C24: R3A | D24: Lateral Face and Doors | E24: 05/07/2023 | F24: Applicable | G24: - | H24: 0 | I24: 0 | J24: - | K24: 0 | L24: -
A25: 01266_23_00137 | B25: REAR GAS SPRING | C25: N2B | D25: Rear Face and Tailgate | E25: 29/05/2023 | F25: Applicable | G25: - | H25: 0 | I25: 0 | J25: - | K25: 0 | L25: -
A26: 01266_22_00518 | B26: CENTRAL AIRBAG DEFLECTOR | C26: U1C | D26: Interior Trims | E26: 45230 | F26: Approved | G26: - | H26: 0 | I26: 0 | J26: - | K26: 0 | L26: -
A27: 01266_22_00759 | B27: FRONT SAFETY BELT STRAP DEVIATOR | C27: U1A | D27: Seats and safety belts | E27: 45215 | F27: Current Update | G27: - | H27: 0 | I27: 0 | J27: - | K27: 0 | L27: -
A28: 01266_22_00760 | B28: FRONT/REAR SOUND DEADENING TUNNEL | C28: X2A | D28: Interior Trims | E28: 18/04/2023 | F28: Applicable | G28: - | H28: 0 | I28: 0 | J28: - | K28: 0 | L28: -
A29: 01266_22_00765 | B29: INSPECTION TRAP | C29: X5B | D29: Rear Face and Tailgate | E29: 45237 | F29: Approved | G29: - | H29: 0 | I29: 0 | J29: - | K29: 0 | L29: -
A30: 01266_23_00140 | B30: DOOR MOUNTED SEAL | C30: W2A | D30: Lateral Face and Doors | E30: 45225 | F30: Approved | G30: - | H30: 0 | I30: 0 | J30: - | K30: 0 | L30: -
A31: 01266_23_00185 | B31: PASSENGER AIRBAG DISABLING CONTROL | C31: U4A | D31: Dashboard and console | E31: 22/05/2023 | F31: Applicable | G31: - | H31: 0 | I31: 0 | J31: - | K31: 0 | L31: -
A32: 01266_23_00186 | B32: FACIA PANEL MAG POUCH LIGHT | C32: Z2M | D32: Dashboard and console | E32: 22/05/2023 | F32: Applicable | G32: - | H32: 0 | I32: 0 | J32: coef | K32: coef | L32: -
A33: 01266_23_00190 | B33: WINDSCREEN DEFROSTING GRID | C33: S1A | D33: NEW | E33: 28/07/2023 | F33: Applicable | G33: - | H33: 0 | I33: 0 | J33: - | K33: 0 | L33: -
A34: 01266_23_00193 | B34: DUCT AIR DISTRIBUTION FACIA PANEL RH/LH | C34: V3A | D34: NEW | E34: 28/07/2023 | F34: Applicable | G34: - | H34: 0 | I34: 0 | J34: 9621385880 RIVET DEMONT 6,5 D22 E3,8 E6 PLAS coef 1 PER PART | K34: coef 1 PER PART | L34: -
A35: 01266_22_00509 | B35: DUCT AIR DISTRIBUTION FACIA PANEL | C35: V3A | D35: NEW | E35: 28/07/2023 | F35: Current Update | G35: - | H35: 0 | I35: 0 | J35: 9621385880 RIVET DEMONT 6,5 D22 E3,8 E6 PLAS coef 1 PER PART | K35: coef 1 PER PART | L35: -
A36: 01266_22_00139 | B36: FACIA PNL MIXER AIR DUCT on DASHBOARD | C36: V3A | E36: 28/07/2023 | F36: Current Update | G36: - | H36: 0 | I36: coef 3 | J36: - | K36: 0 | L36: TX20_2_15
A37: 01266_23_00189 | B37: AIR DIFUSER ADJUSTABLE LH RH FACIA PANEL | C37: V3A | D37: NEW | E37: 05/04/2023 | F37: Current Update | G37: TO CONVERGE coef | H37: 0 | I37: 0 | J37: - | K37: 0 | L37: -
A38: DPTA_DMOV06_0075 | B38: CRASH DETECTION SENSOR | C38: U4A | D38: Seats and safety belts | E38: 24/04/2023 | F38: Update format to do | G38: 7903233029 NUT K H EMB NETT M6X100 AC8 ZNIA3L coef 1 | H38: 1 | I38: 0 | J38: - | K38: 0 | L38: HSP10_8_15
A39: DPTA_DMOV06_0168 | B39: FRONT ARM WIPER BLADE GLASS WIPE | C39: Z6E | D39: Front Face and Hood | E39: 31/04/2024 | F39: Approved | G39: 7903233039 NUT K H RCN M10X150 AC8 ZNIDN3L 4N coef 1 | H39: 1 | I39: 0 | J39: - | K39: 0 | L39: HSP16_25_15
A40: 01266_22_00528 | B40: WATER INPUT HOSE OF BATTERY TRACTION CHARGER | C40: B12 | D40: Engine and Gearbox | E40: 07/04/2023 | F40: Applicable | G40: 7903233042 ECROU KP H EMB M6X100 AC8 ZNIA3L coef 1 | H40: 1 | I40: 0 | J40: - | K40: 0 | L40: HSP10_8_15
...

Sheet Base PFR table
A1: REF part | B1: designation | C1: Consommation | D1: Coef | E1: LOT | F1: DEC | G1: EN Designation | H1: Type vissage | I1: Torque | J1: Tolerance torque | K1: Ref apoqua | L1: apoqua link | M1: Statut | N1: CX_generique | O1: message | P1: type part
A2: 9809840080 | B2: SCREW H RP18 M6X100 L20 AC8 ZLVFGL FP | C2: BDL | D2: 1 | E2: INT | F2: X5E | G2: FRONT/REAR LASHING EYES | H2: VNB | I2: 8 | J2: 15 | K2: 01266_22_00523 | L2: http://docinfogroupe.inetpsa.com/ead/doc/ref.01266_22_00523/v.vc/fiche | M2: Update format to do | O2: Apoqua reference | P2: Fitted part
A3: 7903042051 | B3: NUT K H SOUD M6X100 AC8 | C3: FER | D3: 1 | E3: INT | F3: X5E | G3: FRONT/REAR LASHING EYES | H3: VNB | I3: 8 | J3: 15 | K3: 01266_22_00523 | L3: http://docinfogroupe.inetpsa.com/ead/doc/ref.01266_22_00523/v.vc/fiche | M3: Update format to do | O3: Apoqua reference | P3: Receiving part
A4: 7903233042 | B4: NUT KP H EMB M6X100 AC8 ZNIA3L | C4: BDL | D4: 2 | E4: HYD | F4: G76 | G4: RR BODY HEIGHT SENSOR | H4: VNB | I4: 8 | J4: 15 | K4: 01266_13_00605 | L4: http://docinfogroupe.inetpsa.com/ead/doc/ref.01266_13_00605/v.vc/fiche | M4: Update format to do | N4: CX-00057207 | O4: Apoqua reference | P4: Fitted part
A5: 9818361480 | B5: STUD CL SOUD M6X100 L22 AC8 ZS5 FP | C5: FER | D5: 2 | E5: HYD | F5: G76 | G5: RR BODY HEIGHT SENSOR | H5: VNB | I5: 8 | J5: 15 | K5: 01266_13_00605 | L5: http://docinfogroupe.inetpsa.com/ead/doc/ref.01266_13_00605/v.vc/fiche | M5: Update format to do | N5: CX-00057207 | O5: Apoqua reference | P5: Receiving part
A6: 9677602580 | B6: SCREW % CBLX M10X150 L30 AC10 FP | C6: BDL | D6: 4 | E6: ASS | F6: Y1A | G6: RANK 1 SEAT | H6: VSC | I6: 30 | J6: 15 | K6: 01266_10_00643 | L6: http://docinfogroupe.inetpsa.com/ead/doc/ref.01266_10_00643/v.vc/fiche | M6: Update format to do | N6: CX-00018359 | O6: Apoqua reference | P6: Fitted part
A7: 9674743180 | B7: NUT % C SOUD M10X150 AC C10 | C7: FER | D7: 4 | E7: ASS | F7: Y1A | G7: RANK 1 SEAT | K7: 01266_10_00643 | L7: http://docinfogroupe.inetpsa.com/ead/doc/ref.01266_10_00643/v.vc/fiche | M7: Update format to do | N7: CX-00018359 | O7: Apoqua reference | P7: Receiving part
A8: 9822751380 | B8: SCREW H EMB M6X100 L20 AC8 ZLVFGL FP | C8: BDL | D8: 1 | E8: HYD | F8: G76 | G8: FRT height sensor | H8: VNB | I8: 8 | J8: 15 | K8: 01266_10_00744 | L8: http://docinfogroupe.inetpsa.com/ead/doc/ref.01266_10_00744/v.vc/fiche | M8: Update format to do | N8: CX-00071884 | O8: Apoqua reference | P8: Fitted part
A9: 7903233042 | B9: NUT KP H EMB M6X100 AC8 ZNIA3L | C9: BDL | D9: 2 | E9: EXT | F9: N2A | G9: HOOK SAFETY HOOD | H9: VSB | I9: 8 | J9: 15 | K9: 01266_10_01548 | L9: http://docinfogroupe.inetpsa.com/ead/doc/ref.01266_10_01548/v.vc/fiche | M9: Update format to do | N9: CX-00068446 | O9: Apoqua reference | P9: Fitted part
A10: 9839184780 | B10: SCREW % CL SOUD ANN M6X100 L20 AC8 FP | C10: FER | D10: 2 | E10: EXT | F10: N2A | G10: HOOK SAFETY HOOD | H10: VSB | I10: 8 | J10: 15 | K10: 01266_10_01548 | L10: http://docinfogroupe.inetpsa.com/ead/doc/ref.01266_10_01548/v.vc/fiche | M10: Update format to do | N10: CX-00068446 | O10: Apoqua reference | P10: Receiving part
A11: 9841237880 | B11: SCREW % H EMB ENDUC LS M8x125 L40 AC10 ZLVMNL | C11: BDL | D11: 1 | E11: DIR | F11: E45 | G11: STEERING COLUMN COMPLETE | H11: VSB | I11: 30 | J11: 15 | K11: DITV_ATAT07_0018 | L11: http://docinfogroupe.inetpsa.com/ead/doc/ref.DITV_ATAT07_0018/v.vc/fiche | M11: Update format to do | N11: CX-00021367 | O11: Apoqua reference | P11: Fitted part
A12: 9678660980 | B12: SCREW % FX M8X125 L25 AC8 ZNIDA3L FP | C12: BDL | D12: 2 | E12: OUV | F12: N1E | G12: DOOR STRICKER | H12: VSB | I12: 20 | J12: 15 | K12: DITV_ATAT07_0090 | L12: http://docinfogroupe.inetpsa.com/ead/doc/ref.DITV_ATAT07_0090/v.vc/fiche | M12: Approved | N12: CX-00010571 | O12: Apoqua reference | P12: Fitted part
A13: 7903301290 | B13: SCREW H RCL M6X100 L25 AC8 DACA NOIR CY | C13: BDL | D13: 2 | E13: OUV | F13: N2B | G13: REAR OPENING STRIKER | H13: VNB | I13: 8 | J13: 15 | K13: DPTA_DMOV06_0145 | L13: http://docinfogroupe.inetpsa.com/ead/doc/ref.DPTA_DMOV06_0145/v.vc/fiche | M13: Update format to do | N13: CX-00026604 | O13: Apoqua reference | P13: Fitted part
A14: 9685216780 | B14: SCREW H RC18 M6X100 L30 AC10 ZLVMGL XE | C14: BDL | D14: 2 | E14: OUV | F14: N2B | G14: REAR OPENING STRIKER | H14: VNB | I14: 8 | J14: 15 | K14: DPTA_DMOV06_0145 | L14: http://docinfogroupe.inetpsa.com/ead/doc/ref.DPTA_DMOV06_0145/v.vc/fiche | M14: Update format to do | N14: CX-00014591 | O14: Apoqua reference | P14: Fitted part
A15: 7903042051 | B15: NUT K H SOUD M6X100 AC8 | C15: FER | D15: 2 | E15: OUV | F15: N2B | G15: REAR OPENING STRIKER | K15: DPTA_DMOV06_0145 | L15: http://docinfogroupe.inetpsa.com/ead/doc/ref.DPTA_DMOV06_0145/v.vc/fiche | M15: Update format to do | N15: CX-00026604 | O15: Apoqua reference | P15: Receiving part
A16: 9634473380 | B16: NUT K CSC SERT M6X100 AC8 E0,8 E2 | C16: FER | D16: 2 | E16: OUV | F16: N2B | G16: REAR OPENING STRIKER | K16: DPTA_DMOV06_0145 | L16: http://docinfogroupe.inetpsa.com/ead/doc/ref.DPTA_DMOV06_0145/v.vc/fiche | M16: Update format to do | N16: CX-00026604 | O16: Apoqua reference | P16: Receiving part
A17: 7903042051 | B17: NUT K H SOUD M6X100 AC8 | C17: FER | D17: 2 | E17: OUV | F17: N2B | G17: REAR OPENING STRIKER | K17: DPTA_DMOV06_0145 | L17: http://docinfogroupe.inetpsa.com/ead/doc/ref.DPTA_DMOV06_0145/v.vc/fiche | M17: Update format to do | N17: CX-00014591 | O17: Apoqua reference | P17: Receiving part
A18: 9634473380 | B18: NUT K CSC SERT M6X100 AC8 E0,8 E2 | C18: FER | D18: 2 | E18: OUV | F18: N2B | G18: REAR OPENING STRIKER | K18: DPTA_DMOV06_0145 | L18: http://docinfogroupe.inetpsa.com/ead/doc/ref.DPTA_DMOV06_0145/v.vc/fiche | M18: Update format to do | N18: CX-00014591 | O18: Apoqua reference | P18: Receiving part
A19: 9685216780 | B19: SCREW H RC18 M6X100 L30 AC10 ZLVMGL XE | C19: BDL | D19: 2 | E19: EXT | F19: N2A | G19: HOOD LATCH | H19: VSB | I19: 8 | J19: 15 | K19: DITV_ATAT07_0037 | L19: http://docinfogroupe.inetpsa.com/ead/doc/ref.DITV_ATAT07_0037/v.vc/fiche | M19: Update format to do | N19: CX-00007792 | O19: Apoqua reference | P19: Fitted part
A20: 9849004880 | B20: SCREW % H EMB RP20 M6X100 L60 AC10 ZLVFGL | C20: BDL | D20: 4 | E20: EXT | F20: N2A | G20: HOOD LATCH | H20: VSB | I20: 8 | J20: 15 | K20: DITV_ATAT07_0037 | L20: http://docinfogroupe.inetpsa.com/ead/doc/ref.DITV_ATAT07_0037/v.vc/fiche | M20: Update format to do | N20: CX-00007792 | O20: Apoqua reference | P20: Fitted part
A21: 9675768080 | B21: SCREW CBLX M6X100 L15 AC08 ZNIN3L FP | C21: BDL | D21: 3 | E21: OUV | F21: N1E | G21: DOOR LATCH | H21: VSB | I21: 8 | J21: 15 | K21: DPTA_DMOV06_0013 | L21: http://docinfogroupe.inetpsa.com/ead/doc/ref.DPTA_DMOV06_0013/v.vc/fiche | M21: Update format to do | N21: CX-00007821 | O21: Apoqua reference | P21: Fitted part
A22: 9824674580 | B22: SCREW RLX M6X100 L20 AC8 ZNIN3L FP | C22: BDL | D22: 2 | E22: OUV | F22: N2B | G22: REAR ACCESS LOCK | H22: VNB | I22: 8 | J22: 15 | K22: DPTA_DMOV06_0082 | L22: http://docinfogroupe.inetpsa.com/ead/doc/ref.DPTA_DMOV06_0082/v.vc/fiche | M22: Update format to do | N22: CX-00074606 | O22: Apoqua reference | P22: Fitted part
A23: 9684437480 | B23: SCREW XE EMB TARAUD CASS M6X100 L12 AC9 | C23: BDL | D23: 1 | E23: EEH | F23: N4A | G23: STEERING ANTITHEFT | H23: VNC | I23: 20 | J23: 15 | K23: DITV_ATAT07_0053 | L23: http://docinfogroupe.inetpsa.com/ead/doc/ref.DITV_ATAT07_0053/v.vc/fiche | M23: Update format to do | N23: CX-00026638 | O23: Apoqua reference | P23: Fitted part
A24: 9684437480 | B24: SCREW XE EMB TARAUD CASS M6X100 L12 AC9 | C24: BDL | D24: 1 | E24: EEH | F24: N4A | G24: STEERING ANTITHEFT | K24: DITV_ATAT07_0053 | L24: http://docinfogroupe.inetpsa.com/ead/doc/ref.DITV_ATAT07_0053/v.vc/fiche | M24: Update format to do | N24: CX-00026638 | O24: Apoqua reference | P24: Fitted part
A25: 7903233042 | B25: NUT KP H EMB M6X100 AC8 ZNIA3L | C25: BDL | D25: 1 | E25: OUV | F25: K7F/K7G | G25: DOOR CHECK STAY | H25: VNC | I25: 10 | J25: 15 | K25: DPTA_DMOV06_0016 | L25: http://docinfogroupe.inetpsa.com/ead/doc/ref.DPTA_DMOV06_0016/v.vc/fiche | M25: Approved | N25: CX-00010380 | O25: Apoqua reference | P25: Fitted part
A26: 9678268380 | B26: SCREW CBX RCN M8X125 L30 AC10 ZNIDN3L FP | C26: BDL | D26: 1 | E26: OUV | F26: K7F/K7G | G26: DOOR CHECK STAY | H26: VNB | I26: 30 | J26: 15 | K26: DPTA_DMOV06_0016 | L26: http://docinfogroupe.inetpsa.com/ead/doc/ref.DPTA_DMOV06_0016/v.vc/fiche | M26: Approved | N26: CX-00007681 | O26: Apoqua reference | P26: Fitted part
A27: 9682642180 | B27: NUT C SOUD M8X125 AC C10 NRVT | C27: FER | D27: 1 | E27: OUV | F27: K7F/K7G | G27: DOOR CHECK STAY | K27: DPTA_DMOV06_0016 | L27: http://docinfogroupe.inetpsa.com/ead/doc/ref.DPTA_DMOV06_0016/v.vc/fiche | M27: Approved | N27: CX-00007681 | O27: Apoqua reference | P27: Receiving part
A28: 9684033880 | B28: NUT % H EMB FREIN M14X150 AC8 ZNIA3L | C28: BDL | D28: 1 | E28: LAS | F28: E14 | G28: FRONT SHOCK ABSORBER ELEMENTS | H28: VSC | I28: 100 | J28: 10 | K28: 01266_11_00285 | L28: http://docinfogroupe.inetpsa.com/ead/doc/ref.01266_11_00285/v.vc/fiche | M28: Approved | N28: CX-00019660 | O28: Apoqua reference | P28: Fitted part
A29: 9628107680 | B29: SCREW RLX M8X125 L26 AC10 ZLVMGL CC | C29: BDL | D29: 1 | E29: OUV | F29: K7F/K7G | G29: DOOR HINGE - BODY PLANT | H29: VSB | I29: 30 | J29: 15 | K29: 01266_11_00413 | L29: http://docinfogroupe.inetpsa.com/ead/doc/ref.01266_11_00413/v.vc/fiche | M29: Update format to do | N29: CX-00026265 | O29: Apoqua reference | P29: Fitted part
A30: 9674550680 | B30: SCREW % H RC22 M8X125 L30 AC10 ZLVMGL FP | C30: BDL | D30: 2 | E30: OUV | F30: K7F/K7G | G30: DOOR HINGE - BODY PLANT | H30: VSC | I30: 32 | J30: 15 | K30: 01266_11_00413 | L30: http://docinfogroupe.inetpsa.com/ead/doc/ref.01266_11_00413/v.vc/fiche | M30: Update format to do | N30: CX-00033503 | O30: Apoqua reference | P30: Fitted part
A31: 9674550680 | B31: SCREW % H RC22 M8X125 L30 AC10 ZLVMGL FP | C31: BDL | D31: 4 | E31: PDC | F31: S1A | G31: DASHBOARD ON BODY | H31: VCB | I31: 20 | J31: 15 | K31: 01266_10_00632 | L31: http://docinfogroupe.inetpsa.com/ead/doc/ref.01266_10_00632/v.vc/fiche | M31: Approved | N31: CX-00007731 | O31: Apoqua reference | P31: Fitted part
A32: 9674550080 | B32: SCREW H RCL M8X125 L45 AC8 ZLVMGL FP | C32: BDL | D32: 1 | E32: PDC | F32: S1A | G32: DASHBOARD ON BODY | H32: VNB | I32: 20 | J32: 15 | K32: 01266_10_00632 | L32: http://docinfogroupe.inetpsa.com/ead/doc/ref.01266_10_00632/v.vc/fiche | M32: Approved | N32: CX-00016403 | O32: Apoqua reference | P32: Fitted part
A33: 7903042052 | B33: NUT K H SOUD M8X125 AC8 | C33: FER | D33: 4 | E33: PDC | F33: S1A | G33: DASHBOARD ON BODY | K33: 01266_10_00632 | L33: http://docinfogroupe.inetpsa.com/ead/doc/ref.01266_10_00632/v.vc/fiche | M33: Approved | N33: CX-00007731 | O33: Apoqua reference | P33: Receiving part
A34: 7903233029 | B34: NUT K H EMB NETT M6X100 AC8 ZNIA3L | C34: BDL | D34: 1 | E34: EEH | F34: U4A | G34: CRASH DETECTION SENSOR | H34: VSB | I34: 8 | J34: 15 | K34: DPTA_DMOV06_0075 | L34: http://docinfogroupe.inetpsa.com/ead/doc/ref.DPTA_DMOV06_0075/v.vc/fiche | M34: Update format to do | N34: CX-00010417 | O34: Apoqua reference | P34: Fitted part
A35: 7903011385 | B35: SCREW K CL SOUD ANN M6X100 L25 AC8 CY | C35: FER | D35: 1 | E35: EEH | F35: U4A | G35: CRASH DETECTION SENSOR | K35: DPTA_DMOV06_0075 | L35: http://docinfogroupe.inetpsa.com/ead/doc/ref.DPTA_DMOV06_0075/v.vc/fiche | M35: Update format to do | N35: CX-00010417 | O35: Apoqua reference | P35: Fitted part
A36: 7903233042 | B36: NUT KP H EMB M6X100 AC8 ZNIA3L | C36: BDL | D36: 4 TO 6 | E36: EXT | F36: R3F | G36: REGISTRATION PLATE FINISHER | H36: VNB | I36: 4 | J36: 15 | K36: 01266_09_00156 | L36: http://docinfogroupe.inetpsa.com/ead/doc/ref.01266_09_00156/v.vc/fiche | M36: Update format to do | N36: CX-00026339 | O36: Apoqua reference | P36: Fitted part
A37: 7903233043 | B37: NUT KP H EMB M8X125 AC8 ZNIA3L | C37: BDL | D37: 1 | E37: OUV | F37: Z6E | G37: REAR G/W SQUEEGEE ARM | H37: VNC | I37: 12 | J37: 15 | K37: 01266_22_00359 | L37: http://docinfogroupe.inetpsa.com/ead/doc/ref.01266_22_00359/v.vc/fiche | M37: Update format to do | N37: CX-00010399 | O37: Apoqua reference | P37: Fitted part
A38: 7903233039 | B38: NUT K H RCN M10X150 AC8 ZNIDN3L 4N | C38: BDL | D38: 1 PER WIPER | E38: OUV | F38: Z6E | G38: FRONT ARM WIPER BLADE GLASS WIPE | H38: VSC | I38: 25 | J38: 15 | K38: 01266_23_00189 | L38: http://docinfogroupe.inetpsa.com/ead/doc/ref.01266_23_00189/v.vc/fiche | M38: Update format to do | N38: CX-00010398 | O38: Apoqua reference | P38: Fitted part
A39: 9678268380 | B39: SCREW CBX RCN M8X125 L30 AC10 ZNIDN3L FP | C39: BDL | D39: 2 | E39: OUV | F39: N2B | G39: RR FLAP STABILIZER BALL | H39: VNB | I39: 20 | J39: 15 | K39: DPTA_DMOV05_0966 | L39: http://docinfogroupe.inetpsa.com/ead/doc/ref.DPTA_DMOV05_0966/v.vc/fiche | M39: Update format to do | N39: CX-00015548 | O39: Apoqua reference | P39: Fitted part
A40: 9605782980 | B40: AXE K VIS RCL SPH10 L15 M8X125 L15 AC | C40: BDL | D40: 2 | E40: OUV | F40: N2B | G40: RR FLAP STABILIZER BALL | H40: VNB | I40: 20 | J40: 15 | K40: DPTA_DMOV05_0966 | L40: http://docinfogroupe.inetpsa.com/ead/doc/ref.DPTA_DMOV05_0966/v.vc/fiche | M40: Update format to do | N40: CX-00058491 | O40: Apoqua reference | P40: Fitted part
...

Sheet Feuil1
